Workbook

Sheet SUNPHARMA Beta Calc
C2: SUNPHARMA.NS
A3: Price | B3: Close | C3: Close | D3: Return | E3: Return | H3: Covariance(Market/company) | I3: Variance (Market)
A4: Ticker | B4: ^CNXPHARMA | C4: SUNPHARMA.NS | D4: Nifty | E4: Company | H4: =_xlfn.COVARIANCE.S(D7:D252,E7:E252) -> 9.884811e-05 | I4: =_xlfn.VAR.S(D7:D252) -> 0.00010123143
A5: Date
A6: 45383 | B6: 19207.9 | C6: 1598.6888 | H6: Beta
A7: 45384 | B7: 19185.15 | C7: 1591.8202 | D7: =(B7-B6)/B6 -> -0.0011844085 | E7: =(C7-C6)/C6 -> -0.0042964285 | H7: =H4/I4 -> 0.97645672
A8: 45385 | B8: 19153.051 | C8: 1589.4652 | D8: =(B8-B7)/B7 -> -0.0016731487 | E8: =(C8-C7)/C7 -> -0.0014794262
A9: 45386 | B9: 19125.199 | C9: 1588.9746 | D9: =(B9-B8)/B8 -> -0.001454158 | E9: =(C9-C8)/C8 -> -0.00030865764 | H9: Market Return
A10: 45387 | B10: 19160.75 | C10: 1578.8187 | D10: =(B10-B9)/B9 -> 0.001858845 | E10: =(C10-C9)/C9 -> -0.0063914702 | H10: =AVERAGE(D7:D252) -> 0.00043962859
A11: 45390 | B11: 19218.85 | C11: 1569.6931 | D11: =(B11-B10)/B10 -> 0.00303222 | E11: =(C11-C10)/C10 -> -0.0057800241
A12: 45391 | B12: 19182.301 | C12: 1572.4899 | D12: =(B12-B11)/B11 -> -0.0019017178 | E12: =(C12-C11)/C11 -> 0.0017817196
A13: 45392 | B13: 19117 | C13: 1573.9617 | D13: =(B13-B12)/B12 -> -0.0034042205 | E13: =(C13-C12)/C12 -> 0.00093596899
A14: 45394 | B14: 18788.65 | C14: 1511.113 | D14: =(B14-B13)/B13 -> -0.017175792 | E14: =(C14-C13)/C13 -> -0.039930218
A15: 45397 | B15: 18617.65 | C15: 1511.1622 | D15: =(B15-B14)/B14 -> -0.0091012391 | E15: =(C15-C14)/C14 -> 3.2555034e-05
A16: 45398 | B16: 18695.6 | C16: 1508.7091 | D16: =(B16-B15)/B15 -> 0.0041868451 | E16: =(C16-C15)/C15 -> -0.0016233366
A17: 45400 | B17: 18525.75 | C17: 1487.9557 | D17: =(B17-B16)/B16 -> -0.0090850046 | E17: =(C17-C16)/C16 -> -0.013755745
A18: 45401 | B18: 18404.6 | C18: 1494.2357 | D18: =(B18-B17)/B17 -> -0.0065395674 | E18: =(C18-C17)/C17 -> 0.0042205755
A19: 45404 | B19: 18643 | C19: 1511.2112 | D19: =(B19-B18)/B18 -> 0.012953305 | E19: =(C19-C18)/C18 -> 0.011360633
A20: 45405 | B20: 18463.75 | C20: 1456.8013 | D20: =(B20-B19)/B19 -> -0.0096148689 | E20: =(C20-C19)/C19 -> -0.036004175
A21: 45406 | B21: 18586.199 | C21: 1457.8806 | D21: =(B21-B20)/B20 -> 0.0066318716 | E21: =(C21-C20)/C20 -> 0.00074090113
A22: 45407 | B22: 18878.15 | C22: 1491.6354 | D22: =(B22-B21)/B21 -> 0.015707955 | E22: =(C22-C21)/C21 -> 0.023153309
... A252: 45744 | B252: 21137.449 | C252: 1717.8495 | D252: =(B252-B251)/B251 -> -0.0064723948 | E252: =(C252-C251)/C251 -> 0.0018770124

Sheet Sun Pharmaceutical Industries
C2: Sun Pharmaceutical Industries | P2: SUNPHARMA.NS
P3: Price | Q3: Close | R3: Close | S3: Return | T3: Return | W3: Covariance(Market/company) | X3: Variance (Market)
B4: Balance Sheet of Sun Pharmaceutical Industries (in Rs. Cr.) | C4: 46105 | F4: Profit & Loss account of Sun Pharmaceutical Industries (in Rs. Cr.) | G4: 46105 | P4: Ticker | Q4: ^CNXPHARMA | R4: SUNPHARMA.NS | S4: Nifty | T4: Company | W4: =_xlfn.COVARIANCE.S(S7:S252,T7:T252) -> 9.884811e-05 | X4: =_xlfn.VAR.S(S7:S252) -> 0.00010123143
C5: 12 mths | G5: 12 mths | P5: Date
B6: EQUITIES AND LIABILITIES | F6: INCOME | P6: 45383 | Q6: 19207.9 | R6: 1598.6888 | W6: Beta
B7: SHAREHOLDER'S FUNDS | F7: Revenue From Operations [Gross] | G7: 47758.45 | P7: 45384 | Q7: 19185.15 | R7: 1591.8202 | S7: =(Q7-Q6)/Q6 -> -0.0011844085 | T7: =(R7-R6)/R6 -> -0.0042964285 | W7: =W4/X4 -> 0.97645672
B8: Equity Share Capital | C8: 239.93 | F8: Less: Excise/Sevice Tax/Other Levies | G8: 0 | P8: 45385 | Q8: 19153.051 | R8: 1589.4652 | S8: =(Q8-Q7)/Q7 -> -0.0016731487 | T8: =(R8-R7)/R7 -> -0.0014794262
B9: Total Share Capital | C9: 239.93 | F9: Revenue From Operations [Net] | G9: 47758.45 | P9: 45386 | Q9: 19125.199 | R9: 1588.9746 | S9: =(Q9-Q8)/Q8 -> -0.001454158 | T9: =(R9-R8)/R8 -> -0.00030865764 | W9: Market Return
B10: Reserves and Surplus | C10: 63426.82 | F10: Total Operating Revenues | G10: 48496.85 | P10: 45387 | Q10: 19160.75 | R10: 1578.8187 | S10: =(Q10-Q9)/Q9 -> 0.001858845 | T10: =(R10-R9)/R9 -> -0.0063914702 | W10: =AVERAGE(S7:S252) -> 0.00043962859
B11: Total Reserves and Surplus | C11: 63426.82 | F11: Other Income | G11: 1354.19 | P11: 45390 | Q11: 19218.85 | R11: 1569.6931 | S11: =(Q11-Q10)/Q10 -> 0.00303222 | T11: =(R11-R10)/R10 -> -0.0057800241
B12: Total Shareholders Funds | C12: 63666.75 | F12: Total Revenue | G12: 49851.04 | P12: 45391 | Q12: 19182.301 | R12: 1572.4899 | S12: =(Q12-Q11)/Q11 -> -0.0019017178 | T12: =(R12-R11)/R11 -> 0.0017817196
B13: Minority Interest | C13: 3439.22 | F13: EXPENSES | J13: Total Debt | K13: =C15 + C21 -> 2845.69 | L13: =_xlfn.FORMULATEXT(K13) -> =C15 + C21 | M13: = Longterm borrowings + shortterm borrowings | P13: 45392 | Q13: 19117 | R13: 1573.9617 | S13: =(Q13-Q12)/Q12 -> -0.0034042205 | T13: =(R13-R12)/R12 -> 0.00093596899
B14: NON-CURRENT LIABILITIES | F14: Cost Of Materials Consumed | G14: 6904.33 | J14: DOL | K14: =K27 / K28 -> 3.2751776 | L14: =_xlfn.FORMULATEXT(K14) -> =K27 / K28 | M14: =Contribution/EBIT | P14: 45394 | Q14: 18788.65 | R14: 1511.113 | S14: =(Q14-Q13)/Q13 -> -0.017175792 | T14: =(R14-R13)/R13 -> -0.039930218
B15: Long Term Borrowings | C15: 1.33 | F15: Purchase Of Stock-In Trade | G15: 3466.15 | J15: DFL | K15: =K28 / K29 -> 1.0215072 | L15: =_xlfn.FORMULATEXT(K15) -> =K28 / K29 | M15: =EBIT/EBT | P15: 45397 | Q15: 18617.65 | R15: 1511.1622 | S15: =(Q15-Q14)/Q14 -> -0.0091012391 | T15: =(R15-R14)/R14 -> 3.2555034e-05
B16: Deferred Tax Liabilities [Net] | C16: 155.06 | F16: Operating And Direct Expenses | G16: 630.26 | J16: DTL | K16: =K14 * K15 -> 3.3456176 | L16: =_xlfn.FORMULATEXT(K16) -> =K14 * K15 | M16: =DOL * DFL | P16: 45398 | Q16: 18695.6 | R16: 1508.7091 | S16: =(Q16-Q15)/Q15 -> 0.0041868451 | T16: =(R16-R15)/R15 -> -0.0016233366
B17: Other Long Term Liabilities | C17: 802.23 | F17: Changes In Inventories Of FGWIP And Stock In Trade | G17: 292.13 | J17: Cost of Debt (Rd) | K17: =G19 / (C15 + C21) -> 0.083800414 | L17: =_xlfn.FORMULATEXT(K17) -> =G19 / (C15 + C21) | M17: =Interest/Total Debt | P17: 45400 | Q17: 18525.75 | R17: 1487.9557 | S17: =(Q17-Q16)/Q16 -> -0.0090850046 | T17: =(R17-R16)/R16 -> -0.013755745
B18: Long Term Provisions | C18: 413.89 | F18: Employee Benefit Expenses | G18: 9429.06 | J18: Cost of Equity (Re) | K18: =K33+K31*(K32-K33) -> 0.10975553 | L18: =_xlfn.FORMULATEXT(K18) -> =K33+K31*(K32-K33) | M18: = RF + Beta(Rm-Rf) | P18: 45401 | Q18: 18404.6 | R18: 1494.2357 | S18: =(Q18-Q17)/Q17 -> -0.0065395674 | T18: =(R18-R17)/R17 -> 0.0042205755
B19: Total Non-Current Liabilities | C19: 1372.51 | F19: Finance Costs | G19: 238.47 | J19: Tax Rate | K19: =G31 / G25 -> 0.12982181 | L19: =_xlfn.FORMULATEXT(K19) -> =G31 / G25 | M19: =Tax/EBT | P19: 45404 | Q19: 18643 | R19: 1511.2112 | S19: =(Q19-Q18)/Q18 -> 0.012953305 | T19: =(R19-R18)/R18 -> 0.011360633
B20: CURRENT LIABILITIES | F20: Depreciation And Amortisation Expenses | G20: 238.47 | J20: Weight of Debt | K20: =K13 / (K13 + C12) -> 0.042784327 | L20: =_xlfn.FORMULATEXT(K20) -> =K13 / (K13 + C12) | M20: =Debt/(Debt+Equity) | P20: 45405 | Q20: 18463.75 | R20: 1456.8013 | S20: =(Q20-Q19)/Q19 -> -0.0096148689 | T20: =(R20-R19)/R19 -> -0.036004175
B21: Short Term Borrowings | C21: 2844.36 | F21: Other Expenses | G21: 14751.79 | J21: Weight of Equity | K21: =C12 / (K13 + C12) -> 0.95721567 | L21: =_xlfn.FORMULATEXT(K21) -> =C12 / (K13 + C12) | M21: =Equity/(Debt+Equity) | P21: 45406 | Q21: 18586.199 | R21: 1457.8806 | S21: =(Q21-Q20)/Q20 -> 0.0066318716 | T21: =(R21-R20)/R20 -> 0.00074090113
B22: Trade Payables | C22: 5653.3 | F22: Total Expenses | G22: 38268.83 | J22: WACC | K22: =K21 * K18 + K20 * K17 -> 0.10864506 | L22: =_xlfn.FORMULATEXT(K22) -> =K21 * K18 + K20 * K17 | M22: =(Equity Weight×Cost of Equity)+(Debt Weight×Cost of Debt) | P22: 45407 | Q22: 18878.15 | R22: 1491.6354 | S22: =(Q22-Q21)/Q21 -> 0.015707955 | T22: =(R22-R21)/R21 -> 0.023153309
B23: Other Current Liabilities | C23: 3129.18 | F23: Profit/Loss Before Exceptional, ExtraOrdinary Items And Tax | G23: 11582.21 | P23: 45408 | Q23: 18994.65 | R23: 1478.2906 | S23: =(Q23-Q22)/Q22 -> 0.0061711554 | T23: =(R23-R22)/R22 -> -0.0089463731
B24: Short Term Provisions | C24: 5357.56 | F24: Exceptional Items | G24: -494.32 | P24: 45411 | Q24: 19096.9 | R24: 1493.0582 | S24: =(Q24-Q23)/Q23 -> 0.0053830946 | T24: =(R24-R23)/R23 -> 0.009989631
B25: Total Current Liabilities | C25: 16984.4 | F25: Profit/Loss Before Tax | G25: 11087.89 | J25: Sale | K25: =G9 -> 47758.45 | L25: =_xlfn.FORMULATEXT(K25) -> =G9 | M25: = Revenue From Operations [Net] | P25: 45412 | Q25: 18970.6 | R25: 1473.924 | S25: =(Q25-Q24)/Q24 -> -0.0066136796 | T25: =(R25-R24)/R24 -> -0.012815493
B26: Total Capital And Liabilities | C26: 85462.88 | F26: Tax Expenses-Continued Operations | J26: Variable Cost | K26: =G14+G15+G17 -> 10662.61 | L26: =_xlfn.FORMULATEXT(K26) -> =G14+G15+G17 | M26: = Cost Of Materials Consumed + Purchase Of Stock-In Trade + Changes In Inventories | P26: 45414 | Q26: 19124.449 | R26: 1490.5071 | S26: =(Q26-Q25)/Q25 -> 0.008109897 | T26: =(R26-R25)/R25 -> 0.011251008
B27: ASSETS | F27: Current Tax | G27: 1989.3 | J27: Contribution | K27: =K25-K26 -> 37095.84 | L27: =_xlfn.FORMULATEXT(K27) -> =K25-K26 | M27: = Contribution =Sales - Variable cost | P27: 45415 | Q27: 19133.4 | R27: 1482.8042 | S27: =(Q27-Q26)/Q26 -> 0.00046804861 | T27: =(R27-R26)/R26 -> -0.0051679599
B28: NON-CURRENT ASSETS | F28: Less: MAT Credit Entitlement | G28: 0 | J28: EBIT | K28: =G25+G19 -> 11326.36 | L28: =_xlfn.FORMULATEXT(K28) -> =G25+G19 | M28: = Profit/Loss Before Tax + Finance Costs | P28: 45418 | Q28: 19203.301 | R28: 1500.4666 | S28: =(Q28-Q27)/Q27 -> 0.0036533177 | T28: =(R28-R27)/R27 -> 0.011911454
B29: Tangible Assets | C29: 10192.32 | F29: Deferred Tax | G29: -549.85 | J29: EBT | K29: =G25 -> 11087.89 | L29: =_xlfn.FORMULATEXT(K29) -> =G25 | M29: = Profit/Loss Before Tax | P29: 45419 | Q29: 18846.301 | R29: 1486.9253 | S29: =(Q29-Q28)/Q28 -> -0.018590554 | T29: =(R29-R28)/R28 -> -0.0090246995
B30: Intangible Assets | C30: 4420.11 | F30: Other Direct Taxes | G30: 0 | P30: 45420 | Q30: 18850.85 | R30: 1493.2054 | S30: =(Q30-Q29)/Q29 -> 0.00024136451 | T30: =(R30-R29)/R29 -> 0.0042235823
B31: Capital Work-In-Progress | C31: 1107.73 | F31: Total Tax Expenses | G31: 1439.45 | J31: Beta | K31: ='SUNPHARMA Beta Calc'!H7 -> 0.97645672 | P31: 45421 | Q31: 18437.051 | R31: 1466.6138 | S31: =(Q31-Q30)/Q30 -> -0.021951203 | T31: =(R31-R30)/R30 -> -0.01780845
B32: Fixed Assets | C32: 19966.31 | F32: Profit/Loss After Tax And Before ExtraOrdinary Items | G32: 9648.44 | J32: Market return (Rm) | K32: ='SUNPHARMA Beta Calc'!H10*252 -> 0.11078641 | P32: 45422 | Q32: 18609.449 | R32: 1478.2906 | S32: =(Q32-Q31)/Q31 -> 0.0093506516 | T32: =(R32-R31)/R31 -> 0.0079617962
B33: Non-Current Investments | C33: 6441.23 | F33: Profit/Loss From Continuing Operations | G33: 9648.44 | J33: Risk Free Rate (Rf) | K33: =6.7/100 -> 0.067 | L33: =6.7/100 | M33: = It is Standard | P33: 45425 | Q33: 18939 | R33: 1496.4436 | S33: =(Q33-Q32)/Q32 -> 0.017708787 | T33: =(R33-R32)/R32 -> 0.012279692
B34: Deferred Tax Assets [Net] | C34: 4103.65 | F34: Profit/Loss For The Period | G34: 9648.44 | P34: 45426 | Q34: 18860.85 | R34: 1516.2645 | S34: =(Q34-Q33)/Q33 -> -0.0041264265 | T34: =(R34-R33)/R33 -> 0.013245352
B35: Long Term Loans And Advances | C35: 0.85 | F35: Minority Interest | G35: -33.65 | P35: 45427 | Q35: 18886.551 | R35: 1498.7493 | S35: =(Q35-Q34)/Q34 -> 0.0013626731 | T35: =(R35-R34)/R34 -> -0.011551585
B36: Other Non-Current Assets | C36: 2876.91 | F36: Consolidated Profit/Loss After MI And Associates | G36: 9576.38 | P36: 45428 | Q36: 18996.15 | R36: 1507.4825 | S36: =(Q36-Q35)/Q35 -> 0.0058030506 | T36: =(R36-R35)/R35 -> 0.005827043
B37: Total Non-Current Assets | C37: 41987.9 | F37: OTHER ADDITIONAL INFORMATION | P37: 45429 | Q37: 18981.6 | R37: 1502.6746 | S37: =(Q37-Q36)/Q36 -> -0.00076598579 | T37: =(R37-R36)/R36 -> -0.0031894123
B38: CURRENT ASSETS | F38: EARNINGS PER SHARE | P38: 45433 | Q38: 19205.199 | R38: 1512.0453 | S38: =(Q38-Q37)/Q37 -> 0.011779809 | T38: =(R38-R37)/R37 -> 0.0062360326
B39: Current Investments | C39: 8584.54 | F39: Basic EPS (Rs.) | G39: 40 | P39: 45434 | Q39: 19317.4 | R39: 1510.4261 | S39: =(Q39-Q38)/Q38 -> 0.005842229 | T39: =(R39-R38)/R38 -> -0.0010708281
B40: Inventories | C40: 9868.29 | F40: Diluted EPS (Rs.) | G40: 40 | P40: 45435 | Q40: 19216.35 | R40: 1467.0552 | S40: =(Q40-Q39)/Q39 -> -0.0052310756 | T40: =(R40-R39)/R39 -> -0.028714394
B41: Trade Receivables | C41: 11249.37 | F41: DIVIDEND AND DIVIDEND PERCENTAGE | P41: 45436 | Q41: 19119.5 | R41: 1458.8129 | S41: =(Q41-Q40)/Q40 -> -0.0050399588 | T41: =(R41-R40)/R40 -> -0.0056182683
...

Sheet CIPLA Beta Calc
C2: CIPLA.NS
A3: Price | B3: Close | C3: Close | D3: Return | E3: Return | H3: Covarience(Market/company) | I3: Varience (Market)
A4: Ticker | B4: ^CNXPHARMA | C4: CIPLA.NS | D4: Nifty | E4: Company | H4: =_xlfn.COVARIANCE.S(D7:D252,E7:E252) -> 9.6732111e-05 | I4: =_xlfn.VAR.S(D7:D252) -> 0.00010123143
A5: Date
A6: 45383 | B6: 19207.9 | C6: 1470.343 | H6: Beta
A7: 45384 | B7: 19185.15 | C7: 1461.2678 | D7: =(B7-B6)/B6 -> -0.0011844085 | E7: =(C7-C6)/C6 -> -0.006172162 | H7: =H4/I4 -> 0.95555412
A8: 45385 | B8: 19153.051 | C8: 1443.7058 | D8: =(B8-B7)/B7 -> -0.0016731487 | E8: =(C8-C7)/C7 -> -0.012018339
A9: 45386 | B9: 19125.199 | C9: 1431.9816 | D9: =(B9-B8)/B8 -> -0.001454158 | E9: =(C9-C8)/C8 -> -0.0081209365 | H9: Market Return
A10: 45387 | B10: 19160.75 | C10: 1422.0233 | D10: =(B10-B9)/B9 -> 0.001858845 | E10: =(C10-C9)/C9 -> -0.0069541761 | H10: =AVERAGE(D7:D252) -> 0.00043962859
A11: 45390 | B11: 19218.85 | C11: 1434.8267 | D11: =(B11-B10)/B10 -> 0.00303222 | E11: =(C11-C10)/C10 -> 0.009003611
A12: 45391 | B12: 19182.301 | C12: 1422.9064 | D12: =(B12-B11)/B11 -> -0.0019017178 | E12: =(C12-C11)/C11 -> -0.0083078245
A13: 45392 | B13: 19117 | C13: 1396.0729 | D13: =(B13-B12)/B12 -> -0.0034042205 | E13: =(C13-C12)/C12 -> -0.01885823
A14: 45394 | B14: 18788.65 | C14: 1370.4169 | D14: =(B14-B13)/B13 -> -0.017175792 | E14: =(C14-C13)/C13 -> -0.018377268
A15: 45397 | B15: 18617.65 | C15: 1355.3077 | D15: =(B15-B14)/B14 -> -0.0091012391 | E15: =(C15-C14)/C14 -> -0.011025208
A16: 45398 | B16: 18695.6 | C16: 1349.2247 | D16: =(B16-B15)/B15 -> 0.0041868451 | E16: =(C16-C15)/C15 -> -0.0044882853
A17: 45400 | B17: 18525.75 | C17: 1321.8518 | D17: =(B17-B16)/B16 -> -0.0090850046 | E17: =(C17-C16)/C16 -> -0.020287891
A18: 45401 | B18: 18404.6 | C18: 1320.3311 | D18: =(B18-B17)/B17 -> -0.0065395674 | E18: =(C18-C17)/C17 -> -0.0011504708
A19: 45404 | B19: 18643 | C19: 1329.2592 | D19: =(B19-B18)/B18 -> 0.012953305 | E19: =(C19-C18)/C18 -> 0.0067620167
A20: 45405 | B20: 18463.75 | C20: 1321.2631 | D20: =(B20-B19)/B19 -> -0.0096148689 | E20: =(C20-C19)/C19 -> -0.0060154513
A21: 45406 | B21: 18586.199 | C21: 1371.7904 | D21: =(B21-B20)/B20 -> 0.0066318716 | E21: =(C21-C20)/C20 -> 0.038241699
A22: 45407 | B22: 18878.15 | C22: 1379.6393 | D22: =(B22-B21)/B21 -> 0.015707955 | E22: =(C22-C21)/C21 -> 0.0057216299
... A252: 45744 | B252: 21137.449 | C252: 1426.9567 | D252: =(B252-B251)/B251 -> -0.0064723948 | E252: =(C252-C251)/C251 -> -0.027446271

Sheet CIPLA 
C2: CIPLA | P2: CIPLA.NS
P3: Price | Q3: Close | R3: Close | S3: Return | T3: Return | W3: Covarience(Market/company) | X3: Varience (Market)
B4: Balance Sheet of Cipla (in Rs. Cr.) | C4: 46105 | F4: Profit & Loss account of Cipla (in Rs. Cr.) | G4: 46105 | P4: Ticker | Q4: ^CNXPHARMA | R4: CIPLA.NS | S4: Nifty | T4: Company | W4: =_xlfn.COVARIANCE.S(S7:S252,T7:T252) -> 9.6732111e-05 | X4: =_xlfn.VAR.S(S7:S252) -> 0.00010123143
C5: 12 mths | G5: 12 mths | P5: Date
B6: EQUITIES AND LIABILITIES | F6: INCOME | P6: 45383 | Q6: 19207.9 | R6: 1470.343 | W6: Beta
B7: SHAREHOLDER'S FUNDS | F7: Revenue From Operations [Gross] | G7: 25446.63 | P7: 45384 | Q7: 19185.15 | R7: 1461.2678 | S7: =(Q7-Q6)/Q6 -> -0.0011844085 | T7: =(R7-R6)/R6 -> -0.006172162 | W7: =W4/X4 -> 0.95555412
B8: Equity Share Capital | C8: 161.47 | F8: Less: Excise/Sevice Tax/Other Levies | G8: 0 | P8: 45385 | Q8: 19153.051 | R8: 1443.7058 | S8: =(Q8-Q7)/Q7 -> -0.0016731487 | T8: =(R8-R7)/R7 -> -0.012018339
B9: Total Share Capital | C9: 161.47 | F9: Revenue From Operations [Net] | G9: 25446.63 | P9: 45386 | Q9: 19125.199 | R9: 1431.9816 | S9: =(Q9-Q8)/Q8 -> -0.001454158 | T9: =(R9-R8)/R8 -> -0.0081209365 | W9: Market Return
B10: Reserves and Surplus | C10: 26544.96 | F10: Total Operating Revenues | G10: 25774.09 | P10: 45387 | Q10: 19160.75 | R10: 1422.0233 | S10: =(Q10-Q9)/Q9 -> 0.001858845 | T10: =(R10-R9)/R9 -> -0.0069541761 | W10: =AVERAGE(S7:S252) -> 0.00043962859
B11: Total Reserves and Surplus | C11: 26544.96 | F11: Other Income | G11: 746.57 | P11: 45390 | Q11: 19218.85 | R11: 1434.8267 | S11: =(Q11-Q10)/Q10 -> 0.00303222 | T11: =(R11-R10)/R10 -> 0.009003611
B12: Total Shareholders Funds | C12: 26706.43 | F12: Total Revenue | G12: 26520.66 | P12: 45391 | Q12: 19182.301 | R12: 1422.9064 | S12: =(Q12-Q11)/Q11 -> -0.0019017178 | T12: =(R12-R11)/R11 -> -0.0083078245
B13: Minority Interest | C13: 95.9 | F13: EXPENSES | J13: Total Debt | K13: =C15 + C21 -> 247.02 | L13: =_xlfn.FORMULATEXT(K13) -> =C15 + C21 | M13: = Longterm borrowings + shortterm borrowings | P13: 45392 | Q13: 19117 | R13: 1396.0729 | S13: =(Q13-Q12)/Q12 -> -0.0034042205 | T13: =(R13-R12)/R12 -> -0.01885823
B14: NON-CURRENT LIABILITIES | F14: Cost Of Materials Consumed | G14: 5220.51 | J14: DOL | K14: =K27 / K28 -> 2.8708031 | L14: =_xlfn.FORMULATEXT(K14) -> =K27 / K28 | M14: =Contribution/EBIT | P14: 45394 | Q14: 18788.65 | R14: 1370.4169 | S14: =(Q14-Q13)/Q13 -> -0.017175792 | T14: =(R14-R13)/R13 -> -0.018377268
B15: Long Term Borrowings | C15: 0 | F15: Purchase Of Stock-In Trade | G15: 3536.03 | J15: DFL | K15: =K28 / K29 -> 1.0157632 | L15: =_xlfn.FORMULATEXT(K15) -> =K28 / K29 | M15: =EBIT/EBT | P15: 45397 | Q15: 18617.65 | R15: 1355.3077 | S15: =(Q15-Q14)/Q14 -> -0.0091012391 | T15: =(R15-R14)/R14 -> -0.011025208
B16: Deferred Tax Liabilities [Net] | C16: 185.29 | F16: Operating And Direct Expenses | G16: 640.62 | J16: DTL | K16: =K14 * K15 -> 2.9160561 | L16: =_xlfn.FORMULATEXT(K16) -> =K14 * K15 | M16: =DOL * DFL | P16: 45398 | Q16: 18695.6 | R16: 1349.2247 | S16: =(Q16-Q15)/Q15 -> 0.0041868451 | T16: =(R16-R15)/R15 -> -0.0044882853
B17: Other Long Term Liabilities | C17: 355.17 | F17: Changes In Inventories Of FGWIP And Stock In Trade | G17: 63.03 | J17: Cost of Debt (Rd) | K17: =G19 / (C15 + C21) -> 0.36385718 | L17: =_xlfn.FORMULATEXT(K17) -> =G19 / (C15 + C21) | M17: =Interest/Total Debt | P17: 45400 | Q17: 18525.75 | R17: 1321.8518 | S17: =(Q17-Q16)/Q16 -> -0.0090850046 | T17: =(R17-R16)/R16 -> -0.020287891
B18: Long Term Provisions | C18: 129.26 | F18: Employee Benefit Expenses | G18: 4310.04 | J18: Cost of Equity (Re) | K18: =K33+K31*(K32-K33) -> 0.10884028 | L18: =_xlfn.FORMULATEXT(K18) -> =K33+K31*(K32-K33) | M18: = RF + Beta(Rm-Rf) | P18: 45401 | Q18: 18404.6 | R18: 1320.3311 | S18: =(Q18-Q17)/Q17 -> -0.0065395674 | T18: =(R18-R17)/R17 -> -0.0011504708
B19: Total Non-Current Liabilities | C19: 669.72 | F19: Finance Costs | G19: 89.88 | J19: Tax Rate | K19: =G31 / G25 -> 0.27124117 | L19: =_xlfn.FORMULATEXT(K19) -> =G31 / G25 | M19: =Tax/EBT | P19: 45404 | Q19: 18643 | R19: 1329.2592 | S19: =(Q19-Q18)/Q18 -> 0.012953305 | T19: =(R19-R18)/R18 -> 0.0067620167
B20: CURRENT LIABILITIES | F20: Depreciation And Amortisation Expenses | G20: 1051.02 | J20: Weight of Debt | K20: =K13 / (K13 + C12) -> 0.0091646895 | L20: =_xlfn.FORMULATEXT(K20) -> =K13 / (K13 + C12) | M20: =Debt/(Debt+Equity) | P20: 45405 | Q20: 18463.75 | R20: 1321.2631 | S20: =(Q20-Q19)/Q19 -> -0.0096148689 | T20: =(R20-R19)/R19 -> -0.0060154513
B21: Short Term Borrowings | C21: 247.02 | F21: Other Expenses | G21: 5712.81 | J21: Weight of Equity | K21: =C12 / (K13 + C12) -> 0.99083531 | L21: =_xlfn.FORMULATEXT(K21) -> =C12 / (K13 + C12) | M21: =Equity/(Debt+Equity) | P21: 45406 | Q21: 18586.199 | R21: 1371.7904 | S21: =(Q21-Q20)/Q20 -> 0.0066318716 | T21: =(R21-R20)/R20 -> 0.038241699
B22: Trade Payables | C22: 2473.98 | F22: Total Expenses | G22: 20623.94 | J22: WACC | K22: =K21 * K18 + K20 * K17 -> 0.11117743 | L22: =_xlfn.FORMULATEXT(K22) -> =K21 * K18 + K20 * K17 | M22: =(Equity Weight×Cost of Equity)+(Debt Weight×Cost of Debt) | P22: 45407 | Q22: 18878.15 | R22: 1379.6393 | S22: =(Q22-Q21)/Q21 -> 0.015707955 | T22: =(R22-R21)/R21 -> 0.0057216299
B23: Other Current Liabilities | C23: 913.01 | F23: Profit/Loss Before Exceptional, ExtraOrdinary Items And Tax | G23: 5896.72 | P23: 45408 | Q23: 18994.65 | R23: 1382.5336 | S23: =(Q23-Q22)/Q22 -> 0.0061711554 | T23: =(R23-R22)/R22 -> 0.0020978579
B24: Short Term Provisions | C24: 1611.76 | F24: Exceptional Items | G24: -194.82 | P24: 45411 | Q24: 19096.9 | R24: 1381.4053 | S24: =(Q24-Q23)/Q23 -> 0.0053830946 | T24: =(R24-R23)/R23 -> -0.00081610742
B25: Total Current Liabilities | C25: 5245.77 | F25: Profit/Loss Before Tax | G25: 5701.9 | J25: Sale | K25: =G9 -> 25446.63 | L25: =_xlfn.FORMULATEXT(K25) -> =G9 | M25: = Revenue From Operations [Net] | P25: 45412 | Q25: 18970.6 | R25: 1373.5564 | S25: =(Q25-Q24)/Q24 -> -0.0066136796 | T25: =(R25-R24)/R24 -> -0.0056818061
B26: Total Capital And Liabilities | C26: 32717.82 | F26: Tax Expenses-Continued Operations | J26: Variable Cost | K26: =G14+G15+G17 -> 8819.57 | L26: =_xlfn.FORMULATEXT(K26) -> =G14+G15+G17 | M26: = Cost Of Materials Consumed + Purchase Of Stock-In Trade + Changes In Inventories | P26: 45414 | Q26: 19124.449 | R26: 1393.2278 | S26: =(Q26-Q25)/Q25 -> 0.008109897 | T26: =(R26-R25)/R25 -> 0.014321499
B27: ASSETS | F27: Current Tax | G27: 1696.84 | J27: Contribution | K27: =K25-K26 -> 16627.06 | L27: =_xlfn.FORMULATEXT(K27) -> =K25-K26 | M27: = Contribution =Sales - Variable cost | P27: 45415 | Q27: 19133.4 | R27: 1397.8389 | S27: =(Q27-Q26)/Q26 -> 0.00046804861 | T27: =(R27-R26)/R26 -> 0.0033096411
B28: NON-CURRENT ASSETS | F28: Less: MAT Credit Entitlement | G28: 0 | J28: EBIT | K28: =G25+G19 -> 5791.78 | L28: =_xlfn.FORMULATEXT(K28) -> =G25+G19 | M28: = Profit/Loss Before Tax + Finance Costs | P28: 45418 | Q28: 19203.301 | R28: 1396.5144 | S28: =(Q28-Q27)/Q27 -> 0.0036533177 | T28: =(R28-R27)/R27 -> -0.00094750756
B29: Tangible Assets | C29: 5182.58 | F29: Deferred Tax | G29: -150.25 | J29: EBT | K29: =G25 -> 5701.9 | L29: =_xlfn.FORMULATEXT(K29) -> =G25 | M29: = Profit/Loss Before Tax | P29: 45419 | Q29: 18846.301 | R29: 1360.998 | S29: =(Q29-Q28)/Q28 -> -0.018590554 | T29: =(R29-R28)/R28 -> -0.025432145
B30: Intangible Assets | C30: 1312.6 | F30: Other Direct Taxes | G30: 0 | P30: 45420 | Q30: 18850.85 | R30: 1358.5945 | S30: =(Q30-Q29)/Q29 -> 0.00024136451 | T30: =(R30-R29)/R29 -> -0.0017660308
B31: Capital Work-In-Progress | C31: 864.32 | F31: Total Tax Expenses | G31: 1546.59 | J31: Beta | K31: ='CIPLA Beta Calc'!H7 -> 0.95555412 | P31: 45421 | Q31: 18437.051 | R31: 1333.1346 | S31: =(Q31-Q30)/Q30 -> -0.021951203 | T31: =(R31-R30)/R30 -> -0.018739837
B32: Fixed Assets | C32: 7647.9 | F32: Profit/Loss After Tax And Before ExtraOrdinary Items | G32: 4155.31 | J32: Market return (Rm) | K32: ='CIPLA Beta Calc'!H10*252 -> 0.11078641 | P32: 45422 | Q32: 18609.449 | R32: 1314.2482 | S32: =(Q32-Q31)/Q31 -> 0.0093506516 | T32: =(R32-R31)/R31 -> -0.014166967
B33: Non-Current Investments | C33: 642.21 | F33: Profit/Loss From Continuing Operations | G33: 4155.31 | J33: Risk Free Rate (Rf) | K33: =6.7/100 -> 0.067 | L33: =6.7/100 | M33: = It is Standard | P33: 45425 | Q33: 18939 | R33: 1387.9297 | S33: =(Q33-Q32)/Q32 -> 0.017708787 | T33: =(R33-R32)/R32 -> 0.056063627
B34: Deferred Tax Assets [Net] | C34: 587.8 | F34: Profit/Loss For The Period | G34: 4155.31 | P34: 45426 | Q34: 18860.85 | R34: 1331.7119 | S34: =(Q34-Q33)/Q33 -> -0.0041264265 | T34: =(R34-R33)/R33 -> -0.04050477
B35: Long Term Loans And Advances | C35: 16.98 | F35: Minority Interest | G35: -32.17 | P35: 45427 | Q35: 18886.551 | R35: 1380.1298 | S35: =(Q35-Q34)/Q34 -> 0.0013626731 | T35: =(R35-R34)/R34 -> 0.036357598
B36: Other Non-Current Assets | C36: 1269.48 | F36: Consolidated Profit/Loss After MI And Associates | G36: 4121.55 | P36: 45428 | Q36: 18996.15 | R36: 1394.2578 | S36: =(Q36-Q35)/Q35 -> 0.0058030506 | T36: =(R36-R35)/R35 -> 0.010236756
B37: Total Non-Current Assets | C37: 13276.41 | F37: OTHER ADDITIONAL INFORMATION | P37: 45429 | Q37: 18981.6 | R37: 1372.6244 | S37: =(Q37-Q36)/Q36 -> -0.00076598579 | T37: =(R37-R36)/R36 -> -0.015516085
B38: CURRENT ASSETS | F38: EARNINGS PER SHARE | P38: 45433 | Q38: 19205.199 | R38: 1415.0574 | S38: =(Q38-Q37)/Q37 -> 0.011779809 | T38: =(R38-R37)/R37 -> 0.030913762
B39: Current Investments | C39: 4807.01 | F39: Basic EPS (Rs.) | G39: 51 | P39: 45434 | Q39: 19317.4 | R39: 1454.3019 | S39: =(Q39-Q38)/Q38 -> 0.005842229 | T39: =(R39-R38)/R38 -> 0.027733509
B40: Inventories | C40: 5237.95 | F40: Diluted EPS (Rs.) | G40: 51 | P40: 45435 | Q40: 19216.35 | R40: 1461.0225 | S40: =(Q40-Q39)/Q39 -> -0.0052310756 | T40: =(R40-R39)/R39 -> 0.0046211733
B41: Trade Receivables | C41: 4770.66 | F41: DIVIDEND AND DIVIDEND PERCENTAGE | P41: 45436 | Q41: 19119.5 | R41: 1458.3734 | S41: =(Q41-Q40)/Q40 -> -0.0050399588 | T41: =(R41-R40)/R40 -> -0.0018131466
...

Sheet DR. REDDY Beta Calc
C2: DRREDDY.NS
A3: Price | B3: Close | C3: Close | D3: Return | E3: Return | H3: Covarience(Market/company) | I3: Variance (Market)
A4: Ticker | B4: ^CNXPHARMA | C4: DRREDDY.NS | D4: Nifty | E4: Company | H4: =_xlfn.COVARIANCE.S(D7:D252,E7:E252) -> 8.2296476e-05 | I4: =_xlfn.VAR.S(D7:D252) -> 0.00010123143
A5: Date
A6: 45383 | B6: 19207.9 | C6: 1234.8792 | H6: Beta
A7: 45384 | B7: 19185.15 | C7: 1232.3502 | D7: =(B7-B6)/B6 -> -0.0011844085 | E7: =(C7-C6)/C6 -> -0.0020479175 | H7: =H4/I4 -> 0.81295379
A8: 45385 | B8: 19153.051 | C8: 1209.9952 | D8: =(B8-B7)/B7 -> -0.0016731487 | E8: =(C8-C7)/C7 -> -0.01814012
A9: 45386 | B9: 19125.199 | C9: 1213.5713 | D9: =(B9-B8)/B8 -> -0.001454158 | E9: =(C9-C8)/C8 -> 0.0029554247 | H9: Market Return
A10: 45387 | B10: 19160.75 | C10: 1220.8418 | D10: =(B10-B9)/B9 -> 0.001858845 | E10: =(C10-C9)/C9 -> 0.0059910018 | H10: =AVERAGE(D7:D252) -> 0.00043962859
A11: 45390 | B11: 19218.85 | C11: 1219.9034 | D11: =(B11-B10)/B10 -> 0.00303222 | E11: =(C11-C10)/C10 -> -0.00076861269
A12: 45391 | B12: 19182.301 | C12: 1218.5895 | D12: =(B12-B11)/B11 -> -0.0019017178 | E12: =(C12-C11)/C11 -> -0.0010771056
A13: 45392 | B13: 19117 | C13: 1216.6138 | D13: =(B13-B12)/B12 -> -0.0034042205 | E13: =(C13-C12)/C12 -> -0.0016213073
A14: 45394 | B14: 18788.65 | C14: 1201.9839 | D14: =(B14-B13)/B13 -> -0.017175792 | E14: =(C14-C13)/C13 -> -0.012025084
A15: 45397 | B15: 18617.65 | C15: 1187.5613 | D15: =(B15-B14)/B14 -> -0.0091012391 | E15: =(C15-C14)/C14 -> -0.011999002
A16: 45398 | B16: 18695.6 | C16: 1195.3652 | D16: =(B16-B15)/B15 -> 0.0041868451 | E16: =(C16-C15)/C15 -> 0.0065714125
A17: 45400 | B17: 18525.75 | C17: 1176.9519 | D17: =(B17-B16)/B16 -> -0.0090850046 | E17: =(C17-C16)/C16 -> -0.015403936
A18: 45401 | B18: 18404.6 | C18: 1174.1265 | D18: =(B18-B17)/B17 -> -0.0065395674 | E18: =(C18-C17)/C17 -> -0.0024006414
A19: 45404 | B19: 18643 | C19: 1188.5985 | D19: =(B19-B18)/B18 -> 0.012953305 | E19: =(C19-C18)/C18 -> 0.012325798
A20: 45405 | B20: 18463.75 | C20: 1175.954 | D20: =(B20-B19)/B19 -> -0.0096148689 | E20: =(C20-C19)/C19 -> -0.010638185
A21: 45406 | B21: 18586.199 | C21: 1175.6973 | D21: =(B21-B20)/B20 -> 0.0066318716 | E21: =(C21-C20)/C20 -> -0.00021830265
A22: 45407 | B22: 18878.15 | C22: 1228.6359 | D22: =(B22-B21)/B21 -> 0.015707955 | E22: =(C22-C21)/C21 -> 0.045027406
... A252: 45744 | B252: 21137.449 | C252: 1136.989 | D252: =(B252-B251)/B251 -> -0.0064723948 | E252: =(C252-C251)/C251 -> -0.015487899

Sheet Dr. Reddy's Laboratories
C2: Dr. Reddy's Laboratories | P2: DRREDDY.NS
P3: Price | Q3: Close | R3: Close | S3: Return | T3: Return | W3: Covarience(Market/company) | X3: Variance (Market)
B4: Balance Sheet of Dr Reddys Laboratories (in Rs. Cr.) | C4: 46105 | F4: Profit & Loss account of Dr Reddys Laboratories (in Rs. Cr.) | G4: 46105 | P4: Ticker | Q4: ^CNXPHARMA | R4: DRREDDY.NS | S4: Nifty | T4: Company | W4: =_xlfn.COVARIANCE.S(S7:S252,T7:T252) -> 8.2296476e-05 | X4: =_xlfn.VAR.S(S7:S252) -> 0.00010123143
C5: 12 mths | G5: 12 mths | P5: Date
B6: EQUITIES AND LIABILITIES | F6: INCOME | P6: 45383 | Q6: 19207.9 | R6: 1234.8792 | W6: Beta
B7: SHAREHOLDER'S FUNDS | F7: Revenue From Operations [Gross] | G7: 27916.4 | P7: 45384 | Q7: 19185.15 | R7: 1232.3502 | S7: =(Q7-Q6)/Q6 -> -0.0011844085 | T7: =(R7-R6)/R6 -> -0.0020479175 | W7: =W4/X4 -> 0.81295379
B8: Equity Share Capital | C8: 83.4 | F8: Less: Excise/Sevice Tax/Other Levies | G8: 0 | P8: 45385 | Q8: 19153.051 | R8: 1209.9952 | S8: =(Q8-Q7)/Q7 -> -0.0016731487 | T8: =(R8-R7)/R7 -> -0.01814012
B9: Total Share Capital | C9: 83.4 | F9: Revenue From Operations [Net] | G9: 27916.4 | P9: 45386 | Q9: 19125.199 | R9: 1213.5713 | S9: =(Q9-Q8)/Q8 -> -0.001454158 | T9: =(R9-R8)/R8 -> 0.0029554247 | W9: Market Return
B10: Reserves and Surplus | C10: 28171.4 | F10: Total Operating Revenues | G10: 28011.1 | P10: 45387 | Q10: 19160.75 | R10: 1220.8418 | S10: =(Q10-Q9)/Q9 -> 0.001858845 | T10: =(R10-R9)/R9 -> 0.0059910018 | W10: =AVERAGE(S7:S252) -> 0.00043962859
B11: Total Reserves and Surplus | C11: 28171.4 | F11: Other Income | G11: 894.3 | P11: 45390 | Q11: 19218.85 | R11: 1219.9034 | S11: =(Q11-Q10)/Q10 -> 0.00303222 | T11: =(R11-R10)/R10 -> -0.00076861269
B12: Total Shareholders Funds | C12: 28254.8 | F12: Total Revenue | G12: 28905.4 | P12: 45391 | Q12: 19182.301 | R12: 1218.5895 | S12: =(Q12-Q11)/Q11 -> -0.0019017178 | T12: =(R12-R11)/R11 -> -0.0010771056
B13: Minority Interest | C13: 0 | F13: EXPENSES | J13: Total Debt | K13: =C15 + C21 -> 1652.3 | L13: =_xlfn.FORMULATEXT(K13) -> =C15 + C21 | M13: = Longterm borrowings + shortterm borrowings | P13: 45392 | Q13: 19117 | R13: 1216.6138 | S13: =(Q13-Q12)/Q12 -> -0.0034042205 | T13: =(R13-R12)/R12 -> -0.0016213073
B14: NON-CURRENT LIABILITIES | F14: Cost Of Materials Consumed | G14: 4490.1 | J14: DOL | K14: =K27 / K28 -> 2.6786229 | L14: =_xlfn.FORMULATEXT(K14) -> =K27 / K28 | M14: =Contribution/EBIT | P14: 45394 | Q14: 18788.65 | R14: 1201.9839 | S14: =(Q14-Q13)/Q13 -> -0.017175792 | T14: =(R14-R13)/R13 -> -0.012025084
B15: Long Term Borrowings | C15: 380 | F15: Purchase Of Stock-In Trade | G15: 4399.1 | J15: DFL | K15: =K28 / K29 -> 1.0238092 | L15: =_xlfn.FORMULATEXT(K15) -> =K28 / K29 | M15: =EBIT/EBT | P15: 45397 | Q15: 18617.65 | R15: 1187.5613 | S15: =(Q15-Q14)/Q14 -> -0.0091012391 | T15: =(R15-R14)/R14 -> -0.011999002
B16: Deferred Tax Liabilities [Net] | C16: 84.1 | F16: Operating And Direct Expenses | G16: 0 | J16: DTL | K16: =K14 * K15 -> 2.7423987 | L16: =_xlfn.FORMULATEXT(K16) -> =K14 * K15 | M16: =DOL * DFL | P16: 45398 | Q16: 18695.6 | R16: 1195.3652 | S16: =(Q16-Q15)/Q15 -> 0.0041868451 | T16: =(R16-R15)/R15 -> 0.0065714125
B17: Other Long Term Liabilities | C17: 533 | F17: Changes In Inventories Of FGWIP And Stock In Trade | G17: -680.5 | J17: Cost of Debt (Rd) | K17: =G19 / (C15 + C21) -> 0.10355262 | L17: =_xlfn.FORMULATEXT(K17) -> =G19 / (C15 + C21) | M17: =Interest/Total Debt | P17: 45400 | Q17: 18525.75 | R17: 1176.9519 | S17: =(Q17-Q16)/Q16 -> -0.0090850046 | T17: =(R17-R16)/R16 -> -0.015403936
B18: Long Term Provisions | C18: 23.9 | F18: Employee Benefit Expenses | G18: 5030.1 | J18: Cost of Equity (Re) | K18: =K33+K31*(K32-K33) -> 0.10259632 | L18: =_xlfn.FORMULATEXT(K18) -> =K33+K31*(K32-K33) | M18: = RF + Beta(Rm-Rf) | P18: 45401 | Q18: 18404.6 | R18: 1174.1265 | S18: =(Q18-Q17)/Q17 -> -0.0065395674 | T18: =(R18-R17)/R17 -> -0.0024006414
B19: Total Non-Current Liabilities | C19: 1021 | F19: Finance Costs | G19: 171.1 | J19: Tax Rate | K19: =G31 / G25 -> 0.22586032 | L19: =_xlfn.FORMULATEXT(K19) -> =G31 / G25 | M19: =Tax/EBT | P19: 45404 | Q19: 18643 | R19: 1188.5985 | S19: =(Q19-Q18)/Q18 -> 0.012953305 | T19: =(R19-R18)/R18 -> 0.012325798
B20: CURRENT LIABILITIES | F20: Depreciation And Amortisation Expenses | G20: 1470 | J20: Weight of Debt | K20: =K13 / (K13 + C12) -> 0.055247751 | L20: =_xlfn.FORMULATEXT(K20) -> =K13 / (K13 + C12) | M20: =Debt/(Debt+Equity) | P20: 45405 | Q20: 18463.75 | R20: 1175.954 | S20: =(Q20-Q19)/Q19 -> -0.0096148689 | T20: =(R20-R19)/R19 -> -0.010638185
B21: Short Term Borrowings | C21: 1272.3 | F21: Other Expenses | G21: 6838.9 | J21: Weight of Equity | K21: =C12 / (K13 + C12) -> 0.94475225 | L21: =_xlfn.FORMULATEXT(K21) -> =C12 / (K13 + C12) | M21: =Equity/(Debt+Equity) | P21: 45406 | Q21: 18586.199 | R21: 1175.6973 | S21: =(Q21-Q20)/Q20 -> 0.0066318716 | T21: =(R21-R20)/R20 -> -0.00021830265
B22: Trade Payables | C22: 2614.4 | F22: Total Expenses | G22: 21719.1 | J22: WACC | K22: =K21 * K18 + K20 * K17 -> 0.10264916 | L22: =_xlfn.FORMULATEXT(K22) -> =K21 * K18 + K20 * K17 | M22: =(Equity Weight×Cost of Equity)+(Debt Weight×Cost of Debt) | P22: 45407 | Q22: 18878.15 | R22: 1228.6359 | S22: =(Q22-Q21)/Q21 -> 0.015707955 | T22: =(R22-R21)/R21 -> 0.045027406
B23: Other Current Liabilities | C23: 5009.3 | F23: Profit/Loss Before Exceptional, ExtraOrdinary Items And Tax | G23: 7186.3 | P23: 45408 | Q23: 18994.65 | R23: 1235.225 | S23: =(Q23-Q22)/Q22 -> 0.0061711554 | T23: =(R23-R22)/R22 -> 0.0053629489
B24: Short Term Provisions | C24: 692 | F24: Exceptional Items | G24: 0 | P24: 45411 | Q24: 19096.9 | R24: 1244.1156 | S24: =(Q24-Q23)/Q23 -> 0.0053830946 | T24: =(R24-R23)/R23 -> 0.0071975755
B25: Total Current Liabilities | C25: 9588 | F25: Profit/Loss Before Tax | G25: 7186.3 | J25: Sale | K25: =G9 -> 27916.4 | L25: =_xlfn.FORMULATEXT(K25) -> =G9 | M25: = Revenue From Operations [Net] | P25: 45412 | Q25: 18970.6 | R25: 1225.7811 | S25: =(Q25-Q24)/Q24 -> -0.0066136796 | T25: =(R25-R24)/R24 -> -0.014736953
B26: Total Capital And Liabilities | C26: 38863.8 | F26: Tax Expenses-Continued Operations | J26: Variable Cost | K26: =G14+G15+G17 -> 8208.7 | L26: =_xlfn.FORMULATEXT(K26) -> =G14+G15+G17 | M26: = Cost Of Materials Consumed + Purchase Of Stock-In Trade + Changes In Inventories | P26: 45414 | Q26: 19124.449 | R26: 1242.2189 | S26: =(Q26-Q25)/Q25 -> 0.008109897 | T26: =(R26-R25)/R25 -> 0.013410016
B27: ASSETS | F27: Current Tax | G27: 1945.9 | J27: Contribution | K27: =K25-K26 -> 19707.7 | L27: =_xlfn.FORMULATEXT(K27) -> =K25-K26 | M27: = Contribution =Sales - Variable cost | P27: 45415 | Q27: 19133.4 | R27: 1254.4781 | S27: =(Q27-Q26)/Q26 -> 0.00046804861 | T27: =(R27-R26)/R26 -> 0.0098688545
B28: NON-CURRENT ASSETS | F28: Less: MAT Credit Entitlement | G28: 0 | J28: EBIT | K28: =G25+G19 -> 7357.4 | L28: =_xlfn.FORMULATEXT(K28) -> =G25+G19 | M28: = Profit/Loss Before Tax + Finance Costs | P28: 45418 | Q28: 19203.301 | R28: 1243.3944 | S28: =(Q28-Q27)/Q27 -> 0.0036533177 | T28: =(R28-R27)/R27 -> -0.0088353394
B29: Tangible Assets | C29: 6248.7 | F29: Deferred Tax | G29: -322.8 | J29: EBT | K29: =G25 -> 7186.3 | L29: =_xlfn.FORMULATEXT(K29) -> =G25 | M29: = Profit/Loss Before Tax | P29: 45419 | Q29: 18846.301 | R29: 1236.3116 | S29: =(Q29-Q28)/Q28 -> -0.018590554 | T29: =(R29-R28)/R28 -> -0.0056963129
B30: Intangible Assets | C30: 3626.8 | F30: Other Direct Taxes | G30: 0 | P30: 45420 | Q30: 18850.85 | R30: 1196.5507 | S30: =(Q30-Q29)/Q29 -> 0.00024136451 | T30: =(R30-R29)/R29 -> -0.032160974
B31: Capital Work-In-Progress | C31: 1351 | F31: Total Tax Expenses | G31: 1623.1 | J31: Beta | K31: ='DR. REDDY Beta Calc'!H7 -> 0.81295379 | P31: 45421 | Q31: 18437.051 | R31: 1161.1857 | S31: =(Q31-Q30)/Q30 -> -0.021951203 | T31: =(R31-R30)/R30 -> -0.029555782
B32: Fixed Assets | C32: 11294.8 | F32: Profit/Loss After Tax And Before ExtraOrdinary Items | G32: 5563.2 | J32: Market return (Rm) | K32: ='DR. REDDY Beta Calc'!H10*252 -> 0.11078641 | P32: 45422 | Q32: 18609.449 | R32: 1169.8096 | S32: =(Q32-Q31)/Q31 -> 0.0093506516 | T32: =(R32-R31)/R31 -> 0.0074268066
B33: Non-Current Investments | C33: 525.5 | F33: Profit/Loss From Continuing Operations | G33: 5563.2 | J33: Risk Free Rate (Rf) | K33: =6.7/100 -> 0.067 | L33: =6.7/100 | M33: = It is Standard | P33: 45425 | Q33: 18939 | R33: 1167.3497 | S33: =(Q33-Q32)/Q32 -> 0.017708787 | T33: =(R33-R32)/R32 -> -0.0021027686
B34: Deferred Tax Assets [Net] | C34: 1057.8 | F34: Profit/Loss For The Period | G34: 5563.2 | P34: 45426 | Q34: 18860.85 | R34: 1159.4966 | S34: =(Q34-Q33)/Q33 -> -0.0041264265 | T34: =(R34-R33)/R33 -> -0.0067273322
B35: Long Term Loans And Advances | C35: 0 | F35: Minority Interest | G35: 0 | P35: 45427 | Q35: 18886.551 | R35: 1160.7214 | S35: =(Q35-Q34)/Q34 -> 0.0013626731 | T35: =(R35-R34)/R34 -> 0.0010563666
B36: Other Non-Current Assets | C36: 630.3 | F36: Consolidated Profit/Loss After MI And Associates | G36: 5577.9 | P36: 45428 | Q36: 18996.15 | R36: 1155.8611 | S36: =(Q36-Q35)/Q35 -> 0.0058030506 | T36: =(R36-R35)/R35 -> -0.004187354
B37: Total Non-Current Assets | C37: 14058.5 | F37: OTHER ADDITIONAL INFORMATION | P37: 45429 | Q37: 18981.6 | R37: 1145.8148 | S37: =(Q37-Q36)/Q36 -> -0.00076598579 | T37: =(R37-R36)/R36 -> -0.0086915848
B38: CURRENT ASSETS | F38: EARNINGS PER SHARE | P38: 45433 | Q38: 19205.199 | R38: 1141.9127 | S38: =(Q38-Q37)/Q37 -> 0.011779809 | T38: =(R38-R37)/R37 -> -0.0034055238
B39: Current Investments | C39: 4405 | F39: Basic EPS (Rs.) | G39: 335 | P39: 45434 | Q39: 19317.4 | R39: 1160.277 | S39: =(Q39-Q38)/Q38 -> 0.005842229 | T39: =(R39-R38)/R38 -> 0.016082015
B40: Inventories | C40: 6355.2 | F40: Diluted EPS (Rs.) | G40: 335 | P40: 45435 | Q40: 19216.35 | R40: 1165.2063 | S40: =(Q40-Q39)/Q39 -> -0.0052310756 | T40: =(R40-R39)/R39 -> 0.0042484005
B41: Trade Receivables | C41: 8029.8 | F41: DIVIDEND AND DIVIDEND PERCENTAGE | P41: 45436 | Q41: 19119.5 | R41: 1158.8939 | S41: =(Q41-Q40)/Q40 -> -0.0050399588 | T41: =(R41-R40)/R40 -> -0.0054173908
...

Sheet LUPIN Beta Calc
C2: LUPIN.NS
A3: Price | B3: Close | C3: Close | D3: Return | E3: Return | H3: Covarience(Market/company) | I3: Varience (Market)
A4: Ticker | B4: ^CNXPHARMA | C4: LUPIN.NS | D4: Nifty | E4: Company | H4: =_xlfn.COVARIANCE.S(D7:D252,E7:E252) -> 0.00013062993 | I4: =_xlfn.VAR.S(D7:D252) -> 0.00010123143
A5: Date
A6: 45383 | B6: 19207.9 | C6: 1606.6694 | H6: Beta
A7: 45384 | B7: 19185.15 | C7: 1592.9652 | D7: =(B7-B6)/B6 -> -0.0011844085 | E7: =(C7-C6)/C6 -> -0.0085295851 | H7: =H4/I4 -> 1.2904088
A8: 45385 | B8: 19153.051 | C8: 1588.5126 | D8: =(B8-B7)/B7 -> -0.0016731487 | E8: =(C8-C7)/C7 -> -0.0027951877
A9: 45386 | B9: 19125.199 | C9: 1570.5535 | D9: =(B9-B8)/B8 -> -0.001454158 | E9: =(C9-C8)/C8 -> -0.011305612 | H9: Market Return
A10: 45387 | B10: 19160.75 | C10: 1582.4272 | D10: =(B10-B9)/B9 -> 0.001858845 | E10: =(C10-C9)/C9 -> 0.0075602516 | H10: =AVERAGE(D7:D252) -> 0.00043962859
A11: 45390 | B11: 19218.85 | C11: 1595.0431 | D11: =(B11-B10)/B10 -> 0.00303222 | E11: =(C11-C10)/C10 -> 0.0079724643
A12: 45391 | B12: 19182.301 | C12: 1588.76 | D12: =(B12-B11)/B11 -> -0.0019017178 | E12: =(C12-C11)/C11 -> -0.0039391294
A13: 45392 | B13: 19117 | C13: 1587.7209 | D13: =(B13-B12)/B12 -> -0.0034042205 | E13: =(C13-C12)/C12 -> -0.00065400847
A14: 45394 | B14: 18788.65 | C14: 1605.1853 | D14: =(B14-B13)/B13 -> -0.017175792 | E14: =(C14-C13)/C13 -> 0.010999638
A15: 45397 | B15: 18617.65 | C15: 1592.1736 | D15: =(B15-B14)/B14 -> -0.0091012391 | E15: =(C15-C14)/C14 -> -0.008106054
A16: 45398 | B16: 18695.6 | C16: 1594.4988 | D16: =(B16-B15)/B15 -> 0.0041868451 | E16: =(C16-C15)/C15 -> 0.0014603906
A17: 45400 | B17: 18525.75 | C17: 1577.2819 | D17: =(B17-B16)/B16 -> -0.0090850046 | E17: =(C17-C16)/C16 -> -0.0107977
A18: 45401 | B18: 18404.6 | C18: 1531.2711 | D18: =(B18-B17)/B17 -> -0.0065395674 | E18: =(C18-C17)/C17 -> -0.029170907
A19: 45404 | B19: 18643 | C19: 1586.7809 | D19: =(B19-B18)/B18 -> 0.012953305 | E19: =(C19-C18)/C18 -> 0.036250776
A20: 45405 | B20: 18463.75 | C20: 1563.4292 | D20: =(B20-B19)/B19 -> -0.0096148689 | E20: =(C20-C19)/C19 -> -0.014716389
A21: 45406 | B21: 18586.199 | C21: 1563.3798 | D21: =(B21-B20)/B20 -> 0.0066318716 | E21: =(C21-C20)/C20 -> -3.162182e-05
A22: 45407 | B22: 18878.15 | C22: 1577.6283 | D22: =(B22-B21)/B21 -> 0.015707955 | E22: =(C22-C21)/C21 -> 0.0091139309
... A252: 45744 | B252: 21137.449 | C252: 2015.4149 | D252: =(B252-B251)/B251 -> -0.0064723948 | E252: =(C252-C251)/C251 -> 0.004532305

Sheet LUPIN
C2: LUPIN | P2: LUPIN.NS
P3: Price | Q3: Close | R3: Close | S3: Return | T3: Return | W3: Covarience(Market/company) | X3: Varience (Market)
B4: Balance Sheet of Lupin (in Rs. Cr.) | C4: 46105 | F4: Profit & Loss account of Lupin (in Rs. Cr.) | G4: 46105 | P4: Ticker | Q4: ^CNXPHARMA | R4: LUPIN.NS | S4: Nifty | T4: Company | W4: =_xlfn.COVARIANCE.S(S7:S252,T7:T252) -> 0.00013062993 | X4: =_xlfn.VAR.S(S7:S252) -> 0.00010123143
C5: 12 mths | G5: 12 mths | P5: Date
B6: EQUITIES AND LIABILITIES | F6: INCOME | P6: 45383 | Q6: 19207.9 | R6: 1606.6694 | W6: Beta
B7: SHAREHOLDER'S FUNDS | F7: Revenue From Operations [Gross] | G7: 19656.34 | P7: 45384 | Q7: 19185.15 | R7: 1592.9652 | S7: =(Q7-Q6)/Q6 -> -0.0011844085 | T7: =(R7-R6)/R6 -> -0.0085295851 | W7: =W4/X4 -> 1.2904088
B8: Equity Share Capital | C8: 91.14 | F8: Less: Excise/Sevice Tax/Other Levies | G8: 0 | P8: 45385 | Q8: 19153.051 | R8: 1588.5126 | S8: =(Q8-Q7)/Q7 -> -0.0016731487 | T8: =(R8-R7)/R7 -> -0.0027951877
B9: Total Share Capital | C9: 91.14 | F9: Revenue From Operations [Net] | G9: 19656.34 | P9: 45386 | Q9: 19125.199 | R9: 1570.5535 | S9: =(Q9-Q8)/Q8 -> -0.001454158 | T9: =(R9-R8)/R8 -> -0.011305612 | W9: Market Return
B10: Reserves and Surplus | C10: 14084.7 | F10: Total Operating Revenues | G10: 20010.82 | P10: 45387 | Q10: 19160.75 | R10: 1582.4272 | S10: =(Q10-Q9)/Q9 -> 0.001858845 | T10: =(R10-R9)/R9 -> 0.0075602516 | W10: =AVERAGE(S7:S252) -> 0.00043962859
B11: Total Reserves and Surplus | C11: 14084.7 | F11: Other Income | G11: 120.17 | P11: 45390 | Q11: 19218.85 | R11: 1595.0431 | S11: =(Q11-Q10)/Q10 -> 0.00303222 | T11: =(R11-R10)/R10 -> 0.0079724643
B12: Total Shareholders Funds | C12: 14290.21 | F12: Total Revenue | G12: 20130.99 | P12: 45391 | Q12: 19182.301 | R12: 1588.76 | S12: =(Q12-Q11)/Q11 -> -0.0019017178 | T12: =(R12-R11)/R11 -> -0.0039391294
B13: Minority Interest | C13: 83.16 | F13: EXPENSES | J13: Total Debt | K13: =C15 + C21 -> 2669.91 | L13: =_xlfn.FORMULATEXT(K13) -> =C15 + C21 | M13: = Longterm borrowings + shortterm borrowings | P13: 45392 | Q13: 19117 | R13: 1587.7209 | S13: =(Q13-Q12)/Q12 -> -0.0034042205 | T13: =(R13-R12)/R12 -> -0.00065400847
B14: NON-CURRENT LIABILITIES | F14: Cost Of Materials Consumed | G14: 4142.19 | J14: DOL | K14: =K27 / K28 -> 4.7598541 | L14: =_xlfn.FORMULATEXT(K14) -> =K27 / K28 | M14: =Contribution/EBIT | P14: 45394 | Q14: 18788.65 | R14: 1605.1853 | S14: =(Q14-Q13)/Q13 -> -0.017175792 | T14: =(R14-R13)/R13 -> 0.010999638
B15: Long Term Borrowings | C15: 0 | F15: Purchase Of Stock-In Trade | G15: 2958.72 | J15: DFL | K15: =K28 / K29 -> 1.1286438 | L15: =_xlfn.FORMULATEXT(K15) -> =K28 / K29 | M15: =EBIT/EBT | P15: 45397 | Q15: 18617.65 | R15: 1592.1736 | S15: =(Q15-Q14)/Q14 -> -0.0091012391 | T15: =(R15-R14)/R14 -> -0.008106054
B16: Deferred Tax Liabilities [Net] | C16: 245.87 | F16: Operating And Direct Expenses | G16: 0 | J16: DTL | K16: =K14 * K15 -> 5.3721798 | L16: =_xlfn.FORMULATEXT(K16) -> =K14 * K15 | M16: =DOL * DFL | P16: 45398 | Q16: 18695.6 | R16: 1594.4988 | S16: =(Q16-Q15)/Q15 -> 0.0041868451 | T16: =(R16-R15)/R15 -> 0.0014603906
B17: Other Long Term Liabilities | C17: 500.96 | F17: Changes In Inventories Of FGWIP And Stock In Trade | G17: -457.44 | J17: Cost of Debt (Rd) | K17: =G19 / (C15 + C21) -> 0.1167118 | L17: =_xlfn.FORMULATEXT(K17) -> =G19 / (C15 + C21) | M17: =Interest/Total Debt | P17: 45400 | Q17: 18525.75 | R17: 1577.2819 | S17: =(Q17-Q16)/Q16 -> -0.0090850046 | T17: =(R17-R16)/R16 -> -0.0107977
B18: Long Term Provisions | C18: 375.4 | F18: Employee Benefit Expenses | G18: 3494.57 | J18: Cost of Equity (Re) | K18: =K33+K31*(K32-K33) -> 0.12350236 | L18: =_xlfn.FORMULATEXT(K18) -> =K33+K31*(K32-K33) | M18: = RF + Beta(Rm-Rf) | P18: 45401 | Q18: 18404.6 | R18: 1531.2711 | S18: =(Q18-Q17)/Q17 -> -0.0065395674 | T18: =(R18-R17)/R17 -> -0.029170907
B19: Total Non-Current Liabilities | C19: 1122.23 | F19: Finance Costs | G19: 311.61 | J19: Tax Rate | K19: =G31 / G25 -> 0.20092723 | L19: =_xlfn.FORMULATEXT(K19) -> =G31 / G25 | M19: =Tax/EBT | P19: 45404 | Q19: 18643 | R19: 1586.7809 | S19: =(Q19-Q18)/Q18 -> 0.012953305 | T19: =(R19-R18)/R18 -> 0.036250776
B20: CURRENT LIABILITIES | F20: Depreciation And Amortisation Expenses | G20: 1196.81 | J20: Weight of Debt | K20: =K13 / (K13 + C12) -> 0.15742282 | L20: =_xlfn.FORMULATEXT(K20) -> =K13 / (K13 + C12) | M20: =Debt/(Debt+Equity) | P20: 45405 | Q20: 18463.75 | R20: 1563.4292 | S20: =(Q20-Q19)/Q19 -> -0.0096148689 | T20: =(R20-R19)/R19 -> -0.014716389
B21: Short Term Borrowings | C21: 2669.91 | F21: Other Expenses | G21: 6062.26 | J21: Weight of Equity | K21: =C12 / (K13 + C12) -> 0.84257718 | L21: =_xlfn.FORMULATEXT(K21) -> =C12 / (K13 + C12) | M21: =Equity/(Debt+Equity) | P21: 45406 | Q21: 18586.199 | R21: 1563.3798 | S21: =(Q21-Q20)/Q20 -> 0.0066318716 | T21: =(R21-R20)/R20 -> -3.162182e-05
B22: Trade Payables | C22: 2958.11 | F22: Total Expenses | G22: 17708.72 | J22: WACC | K22: =K21 * K18 + K20 * K17 -> 0.12243337 | L22: =_xlfn.FORMULATEXT(K22) -> =K21 * K18 + K20 * K17 | M22: =(Equity Weight×Cost of Equity)+(Debt Weight×Cost of Debt) | P22: 45407 | Q22: 18878.15 | R22: 1577.6283 | S22: =(Q22-Q21)/Q21 -> 0.015707955 | T22: =(R22-R21)/R21 -> 0.0091139309
B23: Other Current Liabilities | C23: 2348.54 | F23: Profit/Loss Before Exceptional, ExtraOrdinary Items And Tax | G23: 2422.27 | P23: 45408 | Q23: 18994.65 | R23: 1598.9514 | S23: =(Q23-Q22)/Q22 -> 0.0061711554 | T23: =(R23-R22)/R22 -> 0.013515934
B24: Short Term Provisions | C24: 524.94 | F24: Exceptional Items | G24: 0 | P24: 45411 | Q24: 19096.9 | R24: 1620.2253 | S24: =(Q24-Q23)/Q23 -> 0.0053830946 | T24: =(R24-R23)/R23 -> 0.013304923
B25: Total Current Liabilities | C25: 8501.5 | F25: Profit/Loss Before Tax | G25: 2422.27 | J25: Sale | K25: =G9 -> 19656.34 | L25: =_xlfn.FORMULATEXT(K25) -> =G9 | M25: = Revenue From Operations [Net] | P25: 45412 | Q25: 18970.6 | R25: 1628.5864 | S25: =(Q25-Q24)/Q24 -> -0.0066136796 | T25: =(R25-R24)/R24 -> 0.0051604451
B26: Total Capital And Liabilities | C26: 23997.18 | F26: Tax Expenses-Continued Operations | J26: Variable Cost | K26: =G14+G15+G17 -> 6643.47 | L26: =_xlfn.FORMULATEXT(K26) -> =G14+G15+G17 | M26: = Cost Of Materials Consumed + Purchase Of Stock-In Trade + Changes In Inventories | P26: 45414 | Q26: 19124.449 | R26: 1630.3181 | S26: =(Q26-Q25)/Q25 -> 0.008109897 | T26: =(R26-R25)/R25 -> 0.0010633083
B27: ASSETS | F27: Current Tax | G27: 633.85 | J27: Contribution | K27: =K25-K26 -> 13012.87 | L27: =_xlfn.FORMULATEXT(K27) -> =K25-K26 | M27: = Contribution =Sales - Variable cost | P27: 45415 | Q27: 19133.4 | R27: 1637.3434 | S27: =(Q27-Q26)/Q26 -> 0.00046804861 | T27: =(R27-R26)/R26 -> 0.0043091397
B28: NON-CURRENT ASSETS | F28: Less: MAT Credit Entitlement | G28: 0 | J28: EBIT | K28: =G25+G19 -> 2733.88 | L28: =_xlfn.FORMULATEXT(K28) -> =G25+G19 | M28: = Profit/Loss Before Tax + Finance Costs | P28: 45418 | Q28: 19203.301 | R28: 1661.9816 | S28: =(Q28-Q27)/Q27 -> 0.0036533177 | T28: =(R28-R27)/R27 -> 0.015047658
B29: Tangible Assets | C29: 4898.55 | F29: Deferred Tax | G29: -147.15 | J29: EBT | K29: =G25 -> 2422.27 | L29: =_xlfn.FORMULATEXT(K29) -> =G25 | M29: = Profit/Loss Before Tax | P29: 45419 | Q29: 18846.301 | R29: 1593.6578 | S29: =(Q29-Q28)/Q28 -> -0.018590554 | T29: =(R29-R28)/R28 -> -0.0411098
B30: Intangible Assets | C30: 1654.71 | F30: Other Direct Taxes | G30: 0 | P30: 45420 | Q30: 18850.85 | R30: 1599.1494 | S30: =(Q30-Q29)/Q29 -> 0.00024136451 | T30: =(R30-R29)/R29 -> 0.0034458947
B31: Capital Work-In-Progress | C31: 595.67 | F31: Total Tax Expenses | G31: 486.7 | J31: Beta | K31: ='LUPIN Beta Calc'!H7 -> 1.2904088 | P31: 45421 | Q31: 18437.051 | R31: 1567.2882 | S31: =(Q31-Q30)/Q30 -> -0.021951203 | T31: =(R31-R30)/R30 -> -0.019923846
B32: Fixed Assets | C32: 7325.79 | F32: Profit/Loss After Tax And Before ExtraOrdinary Items | G32: 1935.57 | J32: Market return (Rm) | K32: ='LUPIN Beta Calc'!H10*252 -> 0.11078641 | P32: 45422 | Q32: 18609.449 | R32: 1591.6294 | S32: =(Q32-Q31)/Q31 -> 0.0093506516 | T32: =(R32-R31)/R31 -> 0.015530766
B33: Non-Current Investments | C33: 227.7 | F33: Profit/Loss From Continuing Operations | G33: 1935.57 | J33: Risk Free Rate (Rf) | K33: =6.7/100 -> 0.067 | L33: =6.7/100 | M33: = It is Standard | P33: 45425 | Q33: 18939 | R33: 1670.8374 | S33: =(Q33-Q32)/Q32 -> 0.017708787 | T33: =(R33-R32)/R32 -> 0.049765359
B34: Deferred Tax Assets [Net] | C34: 302.53 | F34: Profit/Loss For The Period | G34: 1935.57 | P34: 45426 | Q34: 18860.85 | R34: 1619.9286 | S34: =(Q34-Q33)/Q33 -> -0.0041264265 | T34: =(R34-R33)/R33 -> -0.030469041
B35: Long Term Loans And Advances | C35: 3.57 | F35: Minority Interest | G35: -21.09 | P35: 45427 | Q35: 18886.551 | R35: 1621.858 | S35: =(Q35-Q34)/Q34 -> 0.0013626731 | T35: =(R35-R34)/R34 -> 0.0011910669
B36: Other Non-Current Assets | C36: 364.9 | F36: Consolidated Profit/Loss After MI And Associates | G36: 1914.48 | P36: 45428 | Q36: 18996.15 | R36: 1645.4572 | S36: =(Q36-Q35)/Q35 -> 0.0058030506 | T36: =(R36-R35)/R35 -> 0.01455067
B37: Total Non-Current Assets | C37: 10549.53 | F37: OTHER ADDITIONAL INFORMATION | P37: 45429 | Q37: 18981.6 | R37: 1634.3749 | S37: =(Q37-Q36)/Q36 -> -0.00076598579 | T37: =(R37-R36)/R36 -> -0.0067350738
B38: CURRENT ASSETS | F38: EARNINGS PER SHARE | P38: 45433 | Q38: 19205.199 | R38: 1666.1372 | S38: =(Q38-Q37)/Q37 -> 0.011779809 | T38: =(R38-R37)/R37 -> 0.019433931
B39: Current Investments | C39: 846.93 | F39: Basic EPS (Rs.) | G39: 42 | P39: 45434 | Q39: 19317.4 | R39: 1697.7512 | S39: =(Q39-Q38)/Q38 -> 0.005842229 | T39: =(R39-R38)/R38 -> 0.018974436
B40: Inventories | C40: 4953.9 | F40: Diluted EPS (Rs.) | G40: 42 | P40: 45435 | Q40: 19216.35 | R40: 1615.4758 | S40: =(Q40-Q39)/Q39 -> -0.0052310756 | T40: =(R40-R39)/R39 -> -0.048461394
B41: Trade Receivables | C41: 4692.05 | F41: DIVIDEND AND DIVIDEND PERCENTAGE | P41: 45436 | Q41: 19119.5 | R41: 1597.3684 | S41: =(Q41-Q40)/Q40 -> -0.0050399588 | T41: =(R41-R40)/R40 -> -0.011208723
...

Sheet DIVISLAB Beta Calc
C2: DIVISLAB.NS
A3: Price | B3: Close | C3: Close | D3: Return | E3: Return | H3: Covarience(Market/company) | I3: Varience (Market)
A4: Ticker | B4: ^CNXPHARMA | C4: DIVISLAB.NS | D4: Nifty | E4: Company | H4: =_xlfn.COVARIANCE.S(D7:D252,E7:E252) -> 0.00010872479 | I4: =_xlfn.VAR.S(D7:D252) -> 0.00010123143
A5: Date
A6: 45383 | B6: 19207.9 | C6: 3530.1108 | H6: Beta
A7: 45384 | B7: 19185.15 | C7: 3584.0823 | D7: =(B7-B6)/B6 -> -0.0011844085 | E7: =(C7-C6)/C6 -> 0.015288878 | H7: =H4/I4 -> 1.0740221
A8: 45385 | B8: 19153.051 | C8: 3645.8206 | D8: =(B8-B7)/B7 -> -0.0016731487 | E8: =(C8-C7)/C7 -> 0.017225687
A9: 45386 | B9: 19125.199 | C9: 3694.5977 | D9: =(B9-B8)/B8 -> -0.001454158 | E9: =(C9-C8)/C8 -> 0.013378908 | H9: Market Return
A10: 45387 | B10: 19160.75 | C10: 3708.3997 | D10: =(B10-B9)/B9 -> 0.001858845 | E10: =(C10-C9)/C9 -> 0.0037357253 | H10: =AVERAGE(D7:D252) -> 0.00043962859
A11: 45390 | B11: 19218.85 | C11: 3755.7424 | D11: =(B11-B10)/B10 -> 0.00303222 | E11: =(C11-C10)/C10 -> 0.012766362
A12: 45391 | B12: 19182.301 | C12: 3764.5974 | D12: =(B12-B11)/B11 -> -0.0019017178 | E12: =(C12-C11)/C11 -> 0.0023577177
A13: 45392 | B13: 19117 | C13: 3699.446 | D13: =(B13-B12)/B12 -> -0.0034042205 | E13: =(C13-C12)/C12 -> -0.017306331
A14: 45394 | B14: 18788.65 | C14: 3739.6152 | D14: =(B14-B13)/B13 -> -0.017175792 | E14: =(C14-C13)/C13 -> 0.010858163
A15: 45397 | B15: 18617.65 | C15: 3677.135 | D15: =(B15-B14)/B14 -> -0.0091012391 | E15: =(C15-C14)/C14 -> -0.016707661
A16: 45398 | B16: 18695.6 | C16: 3724.2795 | D16: =(B16-B15)/B15 -> 0.0041868451 | E16: =(C16-C15)/C15 -> 0.012820995
A17: 45400 | B17: 18525.75 | C17: 3669.5659 | D17: =(B17-B16)/B16 -> -0.0090850046 | E17: =(C17-C16)/C16 -> -0.014691062
A18: 45401 | B18: 18404.6 | C18: 3632.7605 | D18: =(B18-B17)/B17 -> -0.0065395674 | E18: =(C18-C17)/C17 -> -0.010029911
A19: 45404 | B19: 18643 | C19: 3697.8628 | D19: =(B19-B18)/B18 -> 0.012953305 | E19: =(C19-C18)/C18 -> 0.017920888
A20: 45405 | B20: 18463.75 | C20: 3728.6821 | D20: =(B20-B19)/B19 -> -0.0096148689 | E20: =(C20-C19)/C19 -> 0.0083343644
A21: 45406 | B21: 18586.199 | C21: 3773.3535 | D21: =(B21-B20)/B20 -> 0.0066318716 | E21: =(C21-C20)/C20 -> 0.011980476
A22: 45407 | B22: 18878.15 | C22: 3803.0356 | D22: =(B22-B21)/B21 -> 0.015707955 | E22: =(C22-C21)/C21 -> 0.0078662465
... A252: 45744 | B252: 21137.449 | C252: 5749.2715 | D252: =(B252-B251)/B251 -> -0.0064723948 | E252: =(C252-C251)/C251 -> -0.016551277

Sheet Divis Labs
C2: DIVIS Laboratories Ltd. | P2: DIVISLAB.NS
P3: Price | Q3: Close | R3: Close | S3: Return | T3: Return | W3: Covarience(Market/company) | X3: Varience (Market)
B4: Balance Sheet of Divis Laboratories (in Rs. Cr.) | C4: 46105 | F4: Profit & Loss account of Divis Laboratories (in Rs. Cr.) | G4: 46105 | P4: Ticker | Q4: ^CNXPHARMA | R4: DIVISLAB.NS | S4: Nifty | T4: Company | W4: =_xlfn.COVARIANCE.S(S7:S252,T7:T252) -> 0.00010872479 | X4: =_xlfn.VAR.S(S7:S252) -> 0.00010123143
C5: 12 mths | G5: 12 mths | P5: Date
B6: EQUITIES AND LIABILITIES | F6: INCOME | P6: 45383 | Q6: 19207.9 | R6: 3530.1108 | W6: Beta
B7: SHAREHOLDER'S FUNDS | F7: Revenue From Operations [Gross] | G7: 7796 | P7: 45384 | Q7: 19185.15 | R7: 3584.0823 | S7: =(Q7-Q6)/Q6 -> -0.0011844085 | T7: =(R7-R6)/R6 -> 0.015288878 | W7: =W4/X4 -> 1.0740221
B8: Equity Share Capital | C8: 53 | F8: Less: Excise/Sevice Tax/Other Levies | G8: 0 | P8: 45385 | Q8: 19153.051 | R8: 3645.8206 | S8: =(Q8-Q7)/Q7 -> -0.0016731487 | T8: =(R8-R7)/R7 -> 0.017225687
B9: Total Share Capital | C9: 53 | F9: Revenue From Operations [Net] | G9: 7796 | P9: 45386 | Q9: 19125.199 | R9: 3694.5977 | S9: =(Q9-Q8)/Q8 -> -0.001454158 | T9: =(R9-R8)/R8 -> 0.013378908 | W9: Market Return
B10: Reserves and Surplus | C10: 13518 | F10: Total Operating Revenues | G10: 7845 | P10: 45387 | Q10: 19160.75 | R10: 3708.3997 | S10: =(Q10-Q9)/Q9 -> 0.001858845 | T10: =(R10-R9)/R9 -> 0.0037357253 | W10: =AVERAGE(S7:S252) -> 0.00043962859
B11: Total Reserves and Surplus | C11: 13518 | F11: Other Income | G11: 339 | P11: 45390 | Q11: 19218.85 | R11: 3755.7424 | S11: =(Q11-Q10)/Q10 -> 0.00303222 | T11: =(R11-R10)/R10 -> 0.012766362
B12: Total Shareholders Funds | C12: 13571 | F12: Total Revenue | G12: 8184 | P12: 45391 | Q12: 19182.301 | R12: 3764.5974 | S12: =(Q12-Q11)/Q11 -> -0.0019017178 | T12: =(R12-R11)/R11 -> 0.0023577177
B13: Minority Interest | C13: 0 | F13: EXPENSES | J13: Total Debt | K13: =C15 + C21 -> 0 | L13: =_xlfn.FORMULATEXT(K13) -> =C15 + C21 | M13: = Longterm borrowings + shortterm borrowings | P13: 45392 | Q13: 19117 | R13: 3699.446 | S13: =(Q13-Q12)/Q12 -> -0.0034042205 | T13: =(R13-R12)/R12 -> -0.017306331
B14: NON-CURRENT LIABILITIES | F14: Cost Of Materials Consumed | G14: 3232 | J14: DOL | K14: =K27 / K28 -> 2.154663 | L14: =_xlfn.FORMULATEXT(K14) -> =K27 / K28 | M14: =Contribution/EBIT | P14: 45394 | Q14: 18788.65 | R14: 3739.6152 | S14: =(Q14-Q13)/Q13 -> -0.017175792 | T14: =(R14-R13)/R13 -> 0.010858163
B15: Long Term Borrowings | C15: 0 | F15: Purchase Of Stock-In Trade | G15: 6 | J15: DFL | K15: =K28 / K29 -> 1.001387 | L15: =_xlfn.FORMULATEXT(K15) -> =K28 / K29 | M15: =EBIT/EBT | P15: 45397 | Q15: 18617.65 | R15: 3677.135 | S15: =(Q15-Q14)/Q14 -> -0.0091012391 | T15: =(R15-R14)/R14 -> -0.016707661
B16: Deferred Tax Liabilities [Net] | C16: 582 | F16: Operating And Direct Expenses | G16: 0 | J16: DTL | K16: =K14 * K15 -> 2.1576514 | L16: =_xlfn.FORMULATEXT(K16) -> =K14 * K15 | M16: =DOL * DFL | P16: 45398 | Q16: 18695.6 | R16: 3724.2795 | S16: =(Q16-Q15)/Q15 -> 0.0041868451 | T16: =(R16-R15)/R15 -> 0.012820995
B17: Other Long Term Liabilities | C17: 2 | F17: Changes In Inventories Of FGWIP And Stock In Trade | G17: -109 | J17: Cost of Debt (Rd) | K17: 0 | L17: - | M17: =Interest/Total Debt | P17: 45400 | Q17: 18525.75 | R17: 3669.5659 | S17: =(Q17-Q16)/Q16 -> -0.0090850046 | T17: =(R17-R16)/R16 -> -0.014691062
B18: Long Term Provisions | C18: 37 | F18: Employee Benefit Expenses | G18: 1094 | J18: Cost of Equity (Re) | K18: =K33+K31*(K32-K33) -> 0.11402757 | L18: =_xlfn.FORMULATEXT(K18) -> =K33+K31*(K32-K33) | M18: = RF + Beta(Rm-Rf) | P18: 45401 | Q18: 18404.6 | R18: 3632.7605 | S18: =(Q18-Q17)/Q17 -> -0.0065395674 | T18: =(R18-R17)/R17 -> -0.010029911
B19: Total Non-Current Liabilities | C19: 621 | F19: Finance Costs | G19: 3 | J19: Tax Rate | K19: =G31 / G25 -> 0.26028664 | L19: =_xlfn.FORMULATEXT(K19) -> =G31 / G25 | M19: =Tax/EBT | P19: 45404 | Q19: 18643 | R19: 3697.8628 | S19: =(Q19-Q18)/Q18 -> 0.012953305 | T19: =(R19-R18)/R18 -> 0.017920888
B20: CURRENT LIABILITIES | F20: Depreciation And Amortisation Expenses | G20: 378 | J20: Weight of Debt | K20: =K13 / (K13 + C12) -> 0 | L20: =_xlfn.FORMULATEXT(K20) -> =K13 / (K13 + C12) | M20: =Debt/(Debt+Equity) | P20: 45405 | Q20: 18463.75 | R20: 3728.6821 | S20: =(Q20-Q19)/Q19 -> -0.0096148689 | T20: =(R20-R19)/R19 -> 0.0083343644
B21: Short Term Borrowings | C21: 0 | F21: Other Expenses | G21: 1417 | J21: Weight of Equity | K21: =C12 / (K13 + C12) -> 1 | L21: =_xlfn.FORMULATEXT(K21) -> =C12 / (K13 + C12) | M21: =Equity/(Debt+Equity) | P21: 45406 | Q21: 18586.199 | R21: 3773.3535 | S21: =(Q21-Q20)/Q20 -> 0.0066318716 | T21: =(R21-R20)/R20 -> 0.011980476
B22: Trade Payables | C22: 824 | F22: Total Expenses | G22: 6021 | J22: WACC | K22: =K21 * K18 + K20 * K17 -> 0.11402757 | L22: =_xlfn.FORMULATEXT(K22) -> =K21 * K18 + K20 * K17 | M22: =(Equity Weight×Cost of Equity)+(Debt Weight×Cost of Debt) | P22: 45407 | Q22: 18878.15 | R22: 3803.0356 | S22: =(Q22-Q21)/Q21 -> 0.015707955 | T22: =(R22-R21)/R21 -> 0.0078662465
B23: Other Current Liabilities | C23: 447 | F23: Profit/Loss Before Exceptional, ExtraOrdinary Items And Tax | G23: 2163 | P23: 45408 | Q23: 18994.65 | R23: 3973.7556 | S23: =(Q23-Q22)/Q22 -> 0.0061711554 | T23: =(R23-R22)/R22 -> 0.044890447
B24: Short Term Provisions | C24: 7 | F24: Exceptional Items | G24: 0 | P24: 45411 | Q24: 19096.9 | R24: 3946.9429 | S24: =(Q24-Q23)/Q23 -> 0.0053830946 | T24: =(R24-R23)/R23 -> -0.0067474567
B25: Total Current Liabilities | C25: 1278 | F25: Profit/Loss Before Tax | G25: 2163 | J25: Sale | K25: =G9 -> 7796 | L25: =_xlfn.FORMULATEXT(K25) -> =G9 | M25: = Revenue From Operations [Net] | P25: 45412 | Q25: 18970.6 | R25: 3959.9534 | S25: =(Q25-Q24)/Q24 -> -0.0066136796 | T25: =(R25-R24)/R24 -> 0.0032963482
B26: Total Capital And Liabilities | C26: 15470 | F26: Tax Expenses-Continued Operations | J26: Variable Cost | K26: =G14+G15+G17 -> 3129 | L26: =_xlfn.FORMULATEXT(K26) -> =G14+G15+G17 | M26: = Cost Of Materials Consumed + Purchase Of Stock-In Trade + Changes In Inventories | P26: 45414 | Q26: 19124.449 | R26: 3922.6038 | S26: =(Q26-Q25)/Q25 -> 0.008109897 | T26: =(R26-R25)/R25 -> -0.0094318306
B27: ASSETS | F27: Current Tax | G27: 514 | J27: Contribution | K27: =K25-K26 -> 4667 | L27: =_xlfn.FORMULATEXT(K27) -> =K25-K26 | M27: = Contribution =Sales - Variable cost | P27: 45415 | Q27: 19133.4 | R27: 3909.0488 | S27: =(Q27-Q26)/Q26 -> 0.00046804861 | T27: =(R27-R26)/R26 -> -0.0034555954
B28: NON-CURRENT ASSETS | F28: Less: MAT Credit Entitlement | G28: 0 | J28: EBIT | K28: =G25+G19 -> 2166 | L28: =_xlfn.FORMULATEXT(K28) -> =G25+G19 | M28: = Profit/Loss Before Tax + Finance Costs | P28: 45418 | Q28: 19203.301 | R28: 3920.9712 | S28: =(Q28-Q27)/Q27 -> 0.0036533177 | T28: =(R28-R27)/R27 -> 0.0030499397
